2022-03-13 01:03:10,194 INFO    MainThread:7531 [wandb_setup.py:_flush():71] setting env: {}
2022-03-13 01:03:10,194 INFO    MainThread:7531 [wandb_setup.py:_flush():71] setting login settings: {}
2022-03-13 01:03:10,194 INFO    MainThread:7531 [wandb_init.py:_log_setup():371] Logging user logs to /home/aiotlab/projects/cuongdm/MEC1/wandb/run-20220313_010310-3ip3jekb/logs/debug.log
2022-03-13 01:03:10,194 INFO    MainThread:7531 [wandb_init.py:_log_setup():372] Logging internal logs to /home/aiotlab/projects/cuongdm/MEC1/wandb/run-20220313_010310-3ip3jekb/logs/debug-internal.log
2022-03-13 01:03:10,194 INFO    MainThread:7531 [wandb_init.py:init():404] calling init triggers
2022-03-13 01:03:10,194 INFO    MainThread:7531 [wandb_init.py:init():409] wandb.init called with sweep_config: {}
config: {}
2022-03-13 01:03:10,194 INFO    MainThread:7531 [wandb_init.py:init():460] starting backend
2022-03-13 01:03:10,194 INFO    MainThread:7531 [backend.py:_multiprocessing_setup():99] multiprocessing start_methods=fork,spawn,forkserver, using: spawn
2022-03-13 01:03:10,200 INFO    MainThread:7531 [backend.py:ensure_launched():216] starting backend process...
2022-03-13 01:03:10,208 INFO    MainThread:7531 [backend.py:ensure_launched():221] started backend process with pid: 8222
2022-03-13 01:03:10,209 INFO    MainThread:7531 [wandb_init.py:init():469] backend started and connected
2022-03-13 01:03:10,214 INFO    MainThread:7531 [wandb_init.py:init():533] updated telemetry
2022-03-13 01:03:10,236 INFO    MainThread:7531 [wandb_init.py:init():563] communicating current version
2022-03-13 01:03:11,291 INFO    MainThread:7531 [wandb_init.py:init():568] got version response upgrade_message: "wandb version 0.12.11 is available!  To upgrade, please run:\n $ pip install wandb --upgrade"

2022-03-13 01:03:11,292 INFO    MainThread:7531 [wandb_init.py:init():578] communicating run to backend with 30 second timeout
2022-03-13 01:03:41,292 INFO    MainThread:7531 [interface_shared.py:_communicate_run():313] couldn't get run from backend
2022-03-13 01:03:41,293 ERROR   MainThread:7531 [wandb_init.py:init():583] backend process timed out
2022-03-13 01:03:41,293 ERROR   MainThread:7531 [wandb_init.py:init():592] encountered error: Error communicating with wandb process
try: wandb.init(settings=wandb.Settings(start_method='fork'))
or:  wandb.init(settings=wandb.Settings(start_method='thread'))
For more info see: https://docs.wandb.ai/library/init#init-start-error
2022-03-13 01:03:41,306 ERROR   MainThread:7531 [wandb_init.py:init():958] error
Traceback (most recent call last):
  File "/home/aiotlab/anaconda3/envs/thanhnt_vaipe/lib/python3.9/site-packages/wandb/sdk/wandb_init.py", line 931, in init
    run = wi.init()
  File "/home/aiotlab/anaconda3/envs/thanhnt_vaipe/lib/python3.9/site-packages/wandb/sdk/wandb_init.py", line 596, in init
    backend.cleanup()
  File "/home/aiotlab/anaconda3/envs/thanhnt_vaipe/lib/python3.9/site-packages/wandb/sdk/backend/backend.py", line 245, in cleanup
    self.interface.join()
  File "/home/aiotlab/anaconda3/envs/thanhnt_vaipe/lib/python3.9/site-packages/wandb/sdk/interface/interface_shared.py", line 458, in join
    super().join()
  File "/home/aiotlab/anaconda3/envs/thanhnt_vaipe/lib/python3.9/site-packages/wandb/sdk/interface/interface.py", line 599, in join
    _ = self._communicate_shutdown()
  File "/home/aiotlab/anaconda3/envs/thanhnt_vaipe/lib/python3.9/site-packages/wandb/sdk/interface/interface_shared.py", line 455, in _communicate_shutdown
    _ = self._communicate(record)
  File "/home/aiotlab/anaconda3/envs/thanhnt_vaipe/lib/python3.9/site-packages/wandb/sdk/interface/interface_shared.py", line 213, in _communicate
    return self._communicate_async(rec, local=local).get(timeout=timeout)
  File "/home/aiotlab/anaconda3/envs/thanhnt_vaipe/lib/python3.9/site-packages/wandb/sdk/interface/interface_shared.py", line 218, in _communicate_async
    raise Exception("The wandb backend process has shutdown")
Exception: The wandb backend process has shutdown
